# 14.1 Try和Finally在异步代码中的缺陷

解决资源安全问题的传统方法是try ... finally结构。

```
  trait Resource
  lazy val acquire: Resource = ???
  def use(resource: Resource): Unit = ???
  def release(resource: Resource): Unit = ???
  lazy val example = {
    val resource = acquire
    try {
      use(resource)
    } finally {
      release(resource)
    }
  }
```

如果在第一行中成功获取了资源，那么我们将立即开始执行try ... finally块。 这保证了无论使用成功完成还是返回异常，都会调用close。
这对于完全同步的代码就足够了。 但是，当我们引入异步和并发时，它开始崩溃，就像几乎所有现代应用程序一样。 让我们看看当我们开始将其翻译为使用Future时会发生什么。 我们将必须创建自己的try变体...最终可以在Future上下文中使用，我们称之为“ensuring”。

```

  import scala.concurrent.{ExecutionContext, Future}
  import scala.util.{Failure, Success}

  trait Resource
  def acquire: Future[Resource] = ???
  def use(resource: Resource): Future[Unit] = ???
  def release(resource: Resource): Future[Unit] = ???

  implicit final class FutureSyntax[+A](future: Future[A]) {
    def ensuring(
      finalizer: Future[Any]
    )(implicit ec: ExecutionContext): Future[A] =
      future.transformWith {
        case Success(a) => finalizer.flatMap(_ => Future.successful(a))
        case Failure(e) => finalizer.flatMap(_ => Future.failed(e))
      }
  }

  implicit val global = scala.concurrent.ExecutionContext.global
  // global: concurrent.ExecutionContextExecutor = scala.concurrent.impl.ExecutionContextImpl@
  lazy val example = acquire.flatMap(resource => use(resource).ensuring(release(resource)))
```

我们向Future添加了一种新方法，称为`ensuring`。确保等待原始的Future完成，然后运行指定的终结器，最后返回原始Future的结果，无论是成功还是失败。请注意，如果终结器抛出异常，则原始异常将丢失。有关此内容的进一步讨论，请参见错误处理一章中的原因讨论。
乍一看似乎还可以。该代码相对简洁，可以确保终结器无论使用成功还是失败都将运行。
问题在于中断。通常，在编写异步和并发代码时，我们必须假设我们可以在任何时候被打断，尤其是可以在组合在一起的效果之间“打断”。如果我们在获取完成执行之后但使用开始执行之前被打断，会发生什么？如果获取不是不可中断的，并且在获取资源的过程中我们被打断了，这将是很常见的，因为在那之后我们将立即检查是否存在中断。在那种情况下，我们将永远不会执行`use`，因为我们被打断了，这也意味着`finalizer`将永远不会运行。因此，我们将无法释放已经获取的资源，从而造成泄漏。
对于Future，这不是问题，因为Future根本不支持中断！但这会产生一个单独的资源问题。由于我们无法中断Future，因此我们无法停止不再需要执行的工作，例如，如果用户导航到网页，查询某些信息并关闭浏览器。这本身会造成资源管理问题。